Workbook

Sheet KPI Summary
B2: BookMetro — Cairo Metro KPI Summary
B3: Recomputed from fact_od_trips.csv + dim_time.csv + fact_service_events.csv | Period: Jan–Dec 2024 | See "Data Notes" tab for data-quality caveats
B5: Total Passengers | D5: Total Revenue (EGP) | F5: Total Trips | H5: Avg Ticket Price (EGP) | J5: Avg Passengers / Trip
B6: =SUM(Raw_MonthlyKPIs!C2:C13) -> 22378852 | D6: =SUM(Raw_MonthlyKPIs!D2:D13) -> 276893482 | F6: =SUM(Raw_MonthlyKPIs!B2:B13) -> 862573 | H6: =SUM(Raw_MonthlyKPIs!D2:D13)/SUM(Raw_MonthlyKPIs!C2:C13) -> 12.372998 | J6: =SUM(Raw_MonthlyKPIs!C2:C13)/SUM(Raw_MonthlyKPIs!B2:B13) -> 25.944299
B9: Monthly KPI Breakdown
B10: Month | C10: Total Trips | D10: Total Passengers | E10: Total Revenue (EGP) | F10: Avg Ticket Price | G10: Avg Passengers/Trip | H10: Service Events | I10: Delay Minutes | J10: Revenue / Passenger | K10: MoM Revenue Growth
B11: Jan | C11: =Raw_MonthlyKPIs!B2 -> 68955 | D11: =Raw_MonthlyKPIs!C2 -> 1793788 | E11: =Raw_MonthlyKPIs!D2 -> 22190476 | F11: =Raw_MonthlyKPIs!E2 -> 12.370735 | G11: =Raw_MonthlyKPIs!F2 -> 26.013893 | H11: =Raw_MonthlyKPIs!G2 -> 67 | I11: =Raw_MonthlyKPIs!H2 -> 3711 | J11: =E11/D11 -> 12.370735 | K11: —
B12: Feb | C12: =Raw_MonthlyKPIs!B3 -> 72226 | D12: =Raw_MonthlyKPIs!C3 -> 1874851 | E12: =Raw_MonthlyKPIs!D3 -> 23177882 | F12: =Raw_MonthlyKPIs!E3 -> 12.362519 | G12: =Raw_MonthlyKPIs!F3 -> 25.958118 | H12: =Raw_MonthlyKPIs!G3 -> 65 | I12: =Raw_MonthlyKPIs!H3 -> 5412 | J12: =E12/D12 -> 12.362519 | K12: =(E12-E11)/E11 -> 0.044496837
B13: Mar | C13: =Raw_MonthlyKPIs!B4 -> 77743 | D13: =Raw_MonthlyKPIs!C4 -> 2018275 | E13: =Raw_MonthlyKPIs!D4 -> 24949787 | F13: =Raw_MonthlyKPIs!E4 -> 12.361936 | G13: =Raw_MonthlyKPIs!F4 -> 25.960858 | H13: =Raw_MonthlyKPIs!G4 -> 76 | I13: =Raw_MonthlyKPIs!H4 -> 5120 | J13: =E13/D13 -> 12.361936 | K13: =(E13-E12)/E12 -> 0.076448098
B14: Apr | C14: =Raw_MonthlyKPIs!B5 -> 69561 | D14: =Raw_MonthlyKPIs!C5 -> 1809523 | E14: =Raw_MonthlyKPIs!D5 -> 22414174 | F14: =Raw_MonthlyKPIs!E5 -> 12.386786 | G14: =Raw_MonthlyKPIs!F5 -> 26.01347 | H14: =Raw_MonthlyKPIs!G5 -> 61 | I14: =Raw_MonthlyKPIs!H5 -> 4019 | J14: =E14/D14 -> 12.386786 | K14: =(E14-E13)/E13 -> -0.10162864
B15: May | C15: =Raw_MonthlyKPIs!B6 -> 74879 | D15: =Raw_MonthlyKPIs!C6 -> 1960043 | E15: =Raw_MonthlyKPIs!D6 -> 24274978 | F15: =Raw_MonthlyKPIs!E6 -> 12.384921 | G15: =Raw_MonthlyKPIs!F6 -> 26.176138 | H15: =Raw_MonthlyKPIs!G6 -> 59 | I15: =Raw_MonthlyKPIs!H6 -> 4251 | J15: =E15/D15 -> 12.384921 | K15: =(E15-E14)/E14 -> 0.083019075
B16: Jun | C16: =Raw_MonthlyKPIs!B7 -> 59029 | D16: =Raw_MonthlyKPIs!C7 -> 1527033 | E16: =Raw_MonthlyKPIs!D7 -> 18909731 | F16: =Raw_MonthlyKPIs!E7 -> 12.383315 | G16: =Raw_MonthlyKPIs!F7 -> 25.8692 | H16: =Raw_MonthlyKPIs!G7 -> 66 | I16: =Raw_MonthlyKPIs!H7 -> 4627 | J16: =E16/D16 -> 12.383315 | K16: =(E16-E15)/E15 -> -0.22101964
B17: Jul | C17: =Raw_MonthlyKPIs!B8 -> 64613 | D17: =Raw_MonthlyKPIs!C8 -> 1682743 | E17: =Raw_MonthlyKPIs!D8 -> 20827923 | F17: =Raw_MonthlyKPIs!E8 -> 12.377364 | G17: =Raw_MonthlyKPIs!F8 -> 26.043412 | H17: =Raw_MonthlyKPIs!G8 -> 61 | I17: =Raw_MonthlyKPIs!H8 -> 3793 | J17: =E17/D17 -> 12.377364 | K17: =(E17-E16)/E16 -> 0.10143941
B18: Aug | C18: =Raw_MonthlyKPIs!B9 -> 67777 | D18: =Raw_MonthlyKPIs!C9 -> 1749123 | E18: =Raw_MonthlyKPIs!D9 -> 21649238 | F18: =Raw_MonthlyKPIs!E9 -> 12.377196 | G18: =Raw_MonthlyKPIs!F9 -> 25.807029 | H18: =Raw_MonthlyKPIs!G9 -> 77 | I18: =Raw_MonthlyKPIs!H9 -> 5404 | J18: =E18/D18 -> 12.377196 | K18: =(E18-E17)/E17 -> 0.039433361
B19: Sep | C19: =Raw_MonthlyKPIs!B10 -> 70562 | D19: =Raw_MonthlyKPIs!C10 -> 1829675 | E19: =Raw_MonthlyKPIs!D10 -> 22674288 | F19: =Raw_MonthlyKPIs!E10 -> 12.392522 | G19: =Raw_MonthlyKPIs!F10 -> 25.930033 | H19: =Raw_MonthlyKPIs!G10 -> 70 | I19: =Raw_MonthlyKPIs!H10 -> 3006 | J19: =E19/D19 -> 12.392522 | K19: =(E19-E18)/E18 -> 0.047348087
B20: Oct | C20: =Raw_MonthlyKPIs!B11 -> 80963 | D20: =Raw_MonthlyKPIs!C11 -> 2103566 | E20: =Raw_MonthlyKPIs!D11 -> 25985158 | F20: =Raw_MonthlyKPIs!E11 -> 12.352908 | G20: =Raw_MonthlyKPIs!F11 -> 25.981819 | H20: =Raw_MonthlyKPIs!G11 -> 58 | I20: =Raw_MonthlyKPIs!H11 -> 3668 | J20: =E20/D20 -> 12.352908 | K20: =(E20-E19)/E19 -> 0.1460187
B21: Nov | C21: =Raw_MonthlyKPIs!B12 -> 76002 | D21: =Raw_MonthlyKPIs!C12 -> 1953486 | E21: =Raw_MonthlyKPIs!D12 -> 24168063 | F21: =Raw_MonthlyKPIs!E12 -> 12.371762 | G21: =Raw_MonthlyKPIs!F12 -> 25.703087 | H21: =Raw_MonthlyKPIs!G12 -> 72 | I21: =Raw_MonthlyKPIs!H12 -> 5276 | J21: =E21/D21 -> 12.371762 | K21: =(E21-E20)/E20 -> -0.069928187
B22: Dec | C22: =Raw_MonthlyKPIs!B13 -> 80263 | D22: =Raw_MonthlyKPIs!C13 -> 2076746 | E22: =Raw_MonthlyKPIs!D13 -> 25671784 | F22: =Raw_MonthlyKPIs!E13 -> 12.361543 | G22: =Raw_MonthlyKPIs!F13 -> 25.874263 | H22: =Raw_MonthlyKPIs!G13 -> 68 | I22: =Raw_MonthlyKPIs!H13 -> 3904 | J22: =E22/D22 -> 12.361543 | K22: =(E22-E21)/E21 -> 0.062219343
B23: Total / Avg | C23: =SUM(C11:C22) -> 862573 | D23: =SUM(D11:D22) -> 22378852 | E23: =SUM(E11:E22) -> 276893482 | F23: =AVERAGE(F11:F22) -> 12.373626 | G23: =AVERAGE(G11:G22) -> 25.944277 | H23: =SUM(H11:H22) -> 800 | I23: =SUM(I11:I22) -> 52191
B26: Top 10 Stations by Total Passengers (2024) | G26: Top 5 Stations by Total Delay Minutes
B27: Rank | C27: Station | D27: Line | E27: Total Passengers | G27: Station | H27: Line | I27: # Delays | J27: Total Delay (min) | K27: Top Reason
B28: 1 | C28: Abbassia | D28: Line3 | E28: 964954 | G28: Saad Zaghloul | H28: Line1 | I28: 32 | J28: 2442 | K28: Mechanical Failure
B29: 2 | C29: Dokki | D29: Line2 | E29: 959418 | G29: Cairo University | H29: Line2 | I29: 27 | J29: 2372 | K29: Signal Failure
B30: 3 | C30: El Mounib | D30: Line2 | E30: 957501 | G30: Ain Shams | H30: Line1 | I30: 26 | J30: 2239 | K30: Power Issue
B31: 4 | C31: Kit Kat | D31: Line3 | E31: 955788 | G31: Maspero | H31: Line3 | I31: 25 | J31: 1884 | K31: Weather Related
B32: 5 | C32: Bab El Shaaria | D32: Line3 | E32: 955230 | G32: Heliopolis Square | H32: Line3 | I32: 27 | J32: 1878 | K32: Weather Related
B33: 6 | C33: Imbaba | D33: Line3 | E33: 954850
B34: 7 | C34: Road El Farag | D34: Line2 | E34: 954332
B35: 8 | C35: Helwan University | D35: Line1 | E35: 954218
B36: 9 | C36: Maspero | D36: Line3 | E36: 952212
B37: 10 | C37: Heliopolis Square | D37: Line3 | E37: 951660

Sheet Seasonal & Ramadan
B2: Seasonal, Monthly & Ramadan/Holiday Analysis
B3: Ramadan / holiday / school-holiday flags from dim_time.csv (hourly grain), joined via time_id — not estimated
B5: Month | C5: Total Passengers | D5: Total Revenue (EGP) | E5: Delay Minutes | F5: Avg Passengers/Trip | H5: Period Type | I5: Days | J5: Avg Passengers/Day | K5: Avg Revenue/Day (EGP) | L5: Avg Ticket Price
B6: ='KPI Summary'!B11 -> Jan | C6: ='KPI Summary'!D11 -> 1793788 | D6: ='KPI Summary'!E11 -> 22190476 | E6: ='KPI Summary'!I11 -> 3711 | F6: ='KPI Summary'!G11 -> 26.013893 | H6: Regular Day | I6: 193 | J6: 66829 | K6: 826772 | L6: 12.37
B7: ='KPI Summary'!B12 -> Feb | C7: ='KPI Summary'!D12 -> 1874851 | D7: ='KPI Summary'!E12 -> 23177882 | E7: ='KPI Summary'!I12 -> 5412 | F7: ='KPI Summary'!G12 -> 25.958118 | H7: Ramadan | I7: 30 | J7: 66596 | K7: 823406 | L7: 12.36
B8: ='KPI Summary'!B13 -> Mar | C8: ='KPI Summary'!D13 -> 2018275 | D8: ='KPI Summary'!E13 -> 24949787 | E8: ='KPI Summary'!I13 -> 5120 | F8: ='KPI Summary'!G13 -> 25.960858 | H8: Public Holiday | I8: 18 | J8: 24432 | K8: 302263 | L8: 12.37
B9: ='KPI Summary'!B14 -> Apr | C9: ='KPI Summary'!D14 -> 1809523 | D9: ='KPI Summary'!E14 -> 22414174 | E9: ='KPI Summary'!I14 -> 4019 | F9: ='KPI Summary'!G14 -> 26.01347 | H9: School Holiday | I9: 125 | J9: 56345 | K9: 697468 | L9: 12.38
B10: ='KPI Summary'!B15 -> May | C10: ='KPI Summary'!D15 -> 1960043 | D10: ='KPI Summary'!E15 -> 24274978 | E10: ='KPI Summary'!I15 -> 4251 | F10: ='KPI Summary'!G15 -> 26.176138
B11: ='KPI Summary'!B16 -> Jun | C11: ='KPI Summary'!D16 -> 1527033 | D11: ='KPI Summary'!E16 -> 18909731 | E11: ='KPI Summary'!I16 -> 4627 | F11: ='KPI Summary'!G16 -> 25.8692 | H11: Note: Ramadan 2024 ran Mar 11 – Apr 9 (30 days). Daily passenger volumes during Ramadan are very close to regular days in this dataset — no significant dip or spike detected at the daily-average level.
B12: ='KPI Summary'!B17 -> Jul | C12: ='KPI Summary'!D17 -> 1682743 | D12: ='KPI Summary'!E17 -> 20827923 | E12: ='KPI Summary'!I17 -> 3793 | F12: ='KPI Summary'!G17 -> 26.043412
B13: ='KPI Summary'!B18 -> Aug | C13: ='KPI Summary'!D18 -> 1749123 | D13: ='KPI Summary'!E18 -> 21649238 | E13: ='KPI Summary'!I18 -> 5404 | F13: ='KPI Summary'!G18 -> 25.807029
B14: ='KPI Summary'!B19 -> Sep | C14: ='KPI Summary'!D19 -> 1829675 | D14: ='KPI Summary'!E19 -> 22674288 | E14: ='KPI Summary'!I19 -> 3006 | F14: ='KPI Summary'!G19 -> 25.930033
B15: ='KPI Summary'!B20 -> Oct | C15: ='KPI Summary'!D20 -> 2103566 | D15: ='KPI Summary'!E20 -> 25985158 | E15: ='KPI Summary'!I20 -> 3668 | F15: ='KPI Summary'!G20 -> 25.981819
B16: ='KPI Summary'!B21 -> Nov | C16: ='KPI Summary'!D21 -> 1953486 | D16: ='KPI Summary'!E21 -> 24168063 | E16: ='KPI Summary'!I21 -> 5276 | F16: ='KPI Summary'!G21 -> 25.703087
B17: ='KPI Summary'!B22 -> Dec | C17: ='KPI Summary'!D22 -> 2076746 | D17: ='KPI Summary'!E22 -> 25671784 | E17: ='KPI Summary'!I22 -> 3904 | F17: ='KPI Summary'!G22 -> 25.874263

Sheet Time of Day
B2: Time of Day & Peak Hour Analysis
B3: Hourly passenger volumes recomputed from fact_od_trips.csv, joined to dim_time.csv
B5: Hour | C5: Period of Day | D5: Total Passengers | E5: Total Trips | F5: Avg Passengers/Trip | H5: Period of Day | I5: Total Passengers | J5: Total Trips
B6: 0 | C6: Offpeak | D6: 319136 | E6: 16445 | F6: 19.41 | H6: Morning Peak | I6: 6391037 | J6: 184995
B7: 1 | C7: Offpeak | D7: 319781 | E7: 16452 | F7: 19.44 | H7: Midday | I7: 6411938 | J7: 328602
B8: 2 | C8: Offpeak | D8: 322109 | E8: 16477 | F8: 19.55 | H8: Evening Peak | I8: 6380937 | J8: 184859
B9: 3 | C9: Offpeak | D9: 326141 | E9: 16697 | F9: 19.53 | H9: Offpeak | I9: 3194940 | J9: 164117
B10: 4 | C10: Offpeak | D10: 311929 | E10: 16272 | F10: 19.17
B11: 5 | C11: Offpeak | D11: 321948 | E11: 16512 | F11: 19.5
B12: 6 | C12: Morning Peak | D12: 2122926 | E12: 61648 | F12: 34.44
B13: 7 | C13: Morning Peak | D13: 2142818 | E13: 61835 | F13: 34.65
B14: 8 | C14: Morning Peak | D14: 2125293 | E14: 61512 | F14: 34.55
B15: 9 | C15: Midday | D15: 803965 | E15: 41278 | F15: 19.48
B16: 10 | C16: Midday | D16: 790963 | E16: 40831 | F16: 19.37
B17: 11 | C17: Midday | D17: 805447 | E17: 41158 | F17: 19.57
B18: 12 | C18: Midday | D18: 804448 | E18: 41045 | F18: 19.6
B19: 13 | C19: Midday | D19: 801597 | E19: 41261 | F19: 19.43
B20: 14 | C20: Midday | D20: 792067 | E20: 40769 | F20: 19.43
B21: 15 | C21: Midday | D21: 803044 | E21: 41035 | F21: 19.57
... B29: 23 | C29: Offpeak | D29: 317883 | E29: 16306 | F29: 19.49

Sheet Station Performance
B2: Station Performance & Service Reliability
B3: Passenger volumes from fact_od_trips.csv; delays from fact_service_events.csv
B5: Top 15 Busiest Stations (Total Passengers, 2024)
B6: Rank | C6: Station | D6: Line | E6: Total Passengers | F6: Total Trips | G6: Popularity
B7: 1 | C7: Abbassia | D7: Line3 | E7: 964954 | F7: 37006 | G7: Very High
B8: 2 | C8: Dokki | D8: Line2 | E8: 959418 | F8: 36886 | G8: Very High
B9: 3 | C9: El Mounib | D9: Line2 | E9: 957501 | F9: 36901 | G9: Very High
B10: 4 | C10: Kit Kat | D10: Line3 | E10: 955788 | F10: 36758 | G10: Very High
B11: 5 | C11: Bab El Shaaria | D11: Line3 | E11: 955230 | F11: 36608 | G11: Very High
B12: 6 | C12: Imbaba | D12: Line3 | E12: 954850 | F12: 36545 | G12: Very High
B13: 7 | C13: Road El Farag | D13: Line2 | E13: 954332 | F13: 36832 | G13: Very High
B14: 8 | C14: Helwan University | D14: Line1 | E14: 954218 | F14: 36765 | G14: Very High
B15: 9 | C15: Maspero | D15: Line3 | E15: 952212 | F15: 36570 | G15: Very High
B16: 10 | C16: Heliopolis Square | D16: Line3 | E16: 951660 | F16: 36565 | G16: Very High
B17: 11 | C17: Sadat | D17: Transfer_Line1/Line2 | E17: 950507 | F17: 36568 | G17: Extreme
B18: 12 | C18: Cairo University | D18: Line2 | E18: 949108 | F18: 36523 | G18: Very High
... B21: 15 | C21: El Malek El Saleh | D21: Line1 | E21: 947133 | F21: 36406 | G21: Very High
B23: Top 10 Stations by Delay Minutes (fact_service_events.csv)
B24: Station | C24: Line | D24: # Delays | E24: Total Delay (min) | F24: Avg Delay (min) | G24: Top Reason
B25: Saad Zaghloul | C25: Line1 | D25: 32 | E25: 2442 | F25: 76.3 | G25: Mechanical Failure
B26: Cairo University | C26: Line2 | D26: 27 | E26: 2372 | F26: 87.9 | G26: Signal Failure
B27: Ain Shams | C27: Line1 | D27: 26 | E27: 2239 | F27: 86.1 | G27: Power Issue
B28: Maspero | C28: Line3 | D28: 25 | E28: 1884 | F28: 75.4 | G28: Weather Related
B29: Heliopolis Square | C29: Line3 | D29: 27 | E29: 1878 | F29: 69.6 | G29: Weather Related
B30: Sayeda Zeinab | C30: Line1 | D30: 23 | E30: 1836 | F30: 79.8 | G30: Mechanical Failure
B31: Dokki | C31: Line2 | D31: 25 | E31: 1790 | F31: 71.6 | G31: Weather Related
B32: Al Shohadaa | C32: Transfer_Line1/Line2 | D32: 26 | E32: 1634 | F32: 62.8 | G32: Track Maintenance
B33: Abbassia | C33: Line3 | D33: 26 | E33: 1596 | F33: 61.4 | G33: Mechanical Failure
B34: Sadat | C34: Transfer_Line1/Line2 | D34: 23 | E34: 1551 | F34: 67.4 | G34: Track Maintenance

Sheet Weather Impact
B2: Weather Impact on Ridership & Revenue
B3: Recomputed from fact_od_trips.csv joined to dim_weather.csv via time_id
B5: Weather | C5: Avg Daily Revenue (EGP) | D5: Avg Passengers/Trip | E5: Total Trips | F5: Avg Temp (°C)
B6: Very Hot | C6: 239015 | D6: 26.28 | E6: 67563 | F6: 39.4
B7: Clear | C7: 210091 | D7: 25.87 | E7: 236941 | F7: 27.1
B8: Extremely Hot | C8: 140865 | D8: 25.83 | E8: 40491 | F8: 39.4
B9: Partly Cloudy | C9: 124363 | D9: 25.45 | E9: 141433 | F9: 27.3
B10: Cool | C10: 124132 | D10: 26.51 | E10: 34498 | F10: 12.2
B11: Pleasant | C11: 120060 | D11: 27.31 | E11: 30617 | F11: 22.7
B12: Mild | C12: 114574 | D12: 28.09 | E12: 28365 | F12: 22.7
B13: Dusty | C13: 103154 | D13: 25.58 | E13: 112160 | F13: 27.5
B14: Heat Wave | C14: 91975 | D14: 25.55 | E14: 26184 | F14: 39.5
B15: Perfect | C15: 90301 | D15: 27.95 | E15: 23289 | F15: 22.8
B16: Sunny | C16: 85460 | D16: 25.36 | E16: 87345 | F16: 27
B17: Cold | C17: 72161 | D17: 25.6 | E17: 20254 | F17: 12
B18: Chilly | C18: 55632 | D18: 26.64 | E18: 13433 | F18: 11.6

Sheet Raw_MonthlyKPIs
A1: month | B1: total_trips | C1: total_passengers | D1: total_revenue_egp | E1: avg_ticket_price | F1: avg_passengers_per_trip | G1: total_service_events | H1: total_delay_minutes
A2: 1 | B2: 68955 | C2: 1793788 | D2: 22190476 | E2: 12.370735 | F2: 26.013893 | G2: 67 | H2: 3711
A3: 2 | B3: 72226 | C3: 1874851 | D3: 23177882 | E3: 12.362519 | F3: 25.958118 | G3: 65 | H3: 5412
A4: 3 | B4: 77743 | C4: 2018275 | D4: 24949787 | E4: 12.361936 | F4: 25.960858 | G4: 76 | H4: 5120
A5: 4 | B5: 69561 | C5: 1809523 | D5: 22414174 | E5: 12.386786 | F5: 26.01347 | G5: 61 | H5: 4019
A6: 5 | B6: 74879 | C6: 1960043 | D6: 24274978 | E6: 12.384921 | F6: 26.176138 | G6: 59 | H6: 4251
A7: 6 | B7: 59029 | C7: 1527033 | D7: 18909731 | E7: 12.383315 | F7: 25.8692 | G7: 66 | H7: 4627
A8: 7 | B8: 64613 | C8: 1682743 | D8: 20827923 | E8: 12.377364 | F8: 26.043412 | G8: 61 | H8: 3793
A9: 8 | B9: 67777 | C9: 1749123 | D9: 21649238 | E9: 12.377196 | F9: 25.807029 | G9: 77 | H9: 5404
A10: 9 | B10: 70562 | C10: 1829675 | D10: 22674288 | E10: 12.392522 | F10: 25.930033 | G10: 70 | H10: 3006
A11: 10 | B11: 80963 | C11: 2103566 | D11: 25985158 | E11: 12.352908 | F11: 25.981819 | G11: 58 | H11: 3668
A12: 11 | B12: 76002 | C12: 1953486 | D12: 24168063 | E12: 12.371762 | F12: 25.703087 | G12: 72 | H12: 5276
A13: 12 | B13: 80263 | C13: 2076746 | D13: 25671784 | E13: 12.361543 | F13: 25.874263 | G13: 68 | H13: 3904

Sheet Raw_StationTotals
A1: station_id | B1: dep_passengers | C1: dep_trips | D1: arr_passengers | E1: arr_trips | F1: total_passengers | G1: total_trips | H1: station_name | I1: line_id | J1: latitude | K1: longitude | L1: is_transfer | M1: popularity_level
A2: 64 | B2: 686899 | C2: 26239 | D2: 278055 | E2: 10767 | F2: 964954 | G2: 37006 | H2: Abbassia | I2: Line3 | J2: 30.0644 | K2: 31.265 | L2: =FALSE() -> FALSE | M2: very_high
A3: 40 | B3: 682722 | C3: 26307 | D3: 276696 | E3: 10579 | F3: 959418 | G3: 36886 | H3: Dokki | I3: Line2 | J3: 30.0386 | K3: 31.21 | L3: =FALSE() -> FALSE | M3: very_high
A4: 33 | B4: 683207 | C4: 26167 | D4: 274294 | E4: 10734 | F4: 957501 | G4: 36901 | H4: El Mounib | I4: Line2 | J4: 29.9811 | K4: 31.2117 | L4: =FALSE() -> FALSE | M4: very_high
A5: 70 | B5: 681854 | C5: 26162 | D5: 273934 | E5: 10596 | F5: 955788 | G5: 36758 | H5: Kit Kat | I5: Line3 | J5: 30.045 | K5: 31.22 | L5: =FALSE() -> FALSE | M5: very_high
A6: 67 | B6: 681197 | C6: 26084 | D6: 274033 | E6: 10524 | F6: 955230 | G6: 36608 | H6: Bab El Shaaria | I6: Line3 | J6: 30.0539 | K6: 31.2478 | L6: =FALSE() -> FALSE | M6: very_high
A7: 72 | B7: 680976 | C7: 26065 | D7: 273874 | E7: 10480 | F7: 954850 | G7: 36545 | H7: Imbaba | I7: Line3 | J7: 30.0394 | K7: 31.2078 | L7: =FALSE() -> FALSE | M7: very_high
A8: 44 | B8: 678586 | C8: 26114 | D8: 275746 | E8: 10718 | F8: 954332 | G8: 36832 | H8: Road El Farag | I8: Line2 | J8: 30.0806 | K8: 31.2344 | L8: =FALSE() -> FALSE | M8: very_high
A9: 3 | B9: 684985 | C9: 26244 | D9: 269233 | E9: 10521 | F9: 954218 | G9: 36765 | H9: Helwan University | I9: Line1 | J9: 29.8697 | K9: 31.3194 | L9: =FALSE() -> FALSE | M9: very_high
A10: 68 | B10: 670849 | C10: 25849 | D10: 281363 | E10: 10721 | F10: 952212 | G10: 36570 | H10: Maspero | I10: Line3 | J10: 30.0506 | K10: 31.2322 | L10: =FALSE() -> FALSE | M10: very_high
A11: 58 | B11: 673754 | C11: 25831 | D11: 277906 | E11: 10734 | F11: 951660 | G11: 36565 | H11: Heliopolis Square | I11: Line3 | J11: 30.0944 | K11: 31.3058 | L11: =FALSE() -> FALSE | M11: very_high
A12: 77 | B12: 669973 | C12: 25856 | D12: 280534 | E12: 10712 | F12: 950507 | G12: 36568 | H12: Sadat | I12: Transfer_Line1/Line2 | J12: 30.0444 | K12: 31.2344 | L12: =TRUE() -> TRUE | M12: extreme
A13: 38 | B13: 669980 | C13: 25770 | D13: 279128 | E13: 10753 | F13: 949108 | G13: 36523 | H13: Cairo University | I13: Line2 | J13: 30.0256 | K13: 31.2083 | L13: =FALSE() -> FALSE | M13: very_high
A14: 18 | B14: 673223 | C14: 25922 | D14: 275424 | E14: 10449 | F14: 948647 | G14: 36371 | H14: Saad Zaghloul | I14: Line1 | J14: 30.0372 | K14: 31.2381 | L14: =FALSE() -> FALSE | M14: very_high
A15: 50 | B15: 672517 | C15: 25970 | D15: 276107 | E15: 10574 | F15: 948624 | G15: 36544 | H15: Adly Mansour | I15: Line3 | J15: 30.1472 | K15: 31.4214 | L15: =FALSE() -> FALSE | M15: very_high
A16: 16 | B16: 669015 | C16: 25797 | D16: 278118 | E16: 10609 | F16: 947133 | G16: 36406 | H16: El Malek El Saleh | I16: Line1 | J16: 30.0181 | K16: 31.2364 | L16: =FALSE() -> FALSE | M16: very_high
A17: 41 | B17: 673644 | C17: 25875 | D17: 273245 | E17: 10556 | F17: 946889 | G17: 36431 | H17: Opera | I17: Line2 | J17: 30.0422 | K17: 31.2247 | L17: =FALSE() -> FALSE | M17: very_high
A18: 80 | B18: 672930 | C18: 25895 | D18: 272327 | E18: 10580 | F18: 945257 | G18: 36475 | H18: Nasser | I18: Transfer_Line1/Line3 | J18: 30.0533 | K18: 31.2383 | L18: =TRUE() -> TRUE | M18: very_high
A19: 49 | B19: 670577 | C19: 25848 | D19: 274604 | E19: 10591 | F19: 945181 | G19: 36439 | H19: Shubra El Kheima | I19: Line2 | J19: 30.1222 | K19: 31.2144 | L19: =FALSE() -> FALSE | M19: very_high
A20: 29 | B20: 673899 | C20: 25971 | D20: 271075 | E20: 10529 | F20: 944974 | G20: 36500 | H20: Ain Shams | I20: Line1 | J20: 30.1311 | K20: 31.3194 | L20: =FALSE() -> FALSE | M20: very_high
A21: 36 | B21: 670618 | C21: 25823 | D21: 274178 | E21: 10576 | F21: 944796 | G21: 36399 | H21: Giza | I21: Line2 | J21: 30.0131 | K21: 31.2067 | L21: =FALSE() -> FALSE | M21: very_high
A22: 62 | B22: 671727 | C22: 26292 | D22: 272701 | E22: 10597 | F22: 944428 | G22: 36889 | H22: Stadium | I22: Line3 | J22: 30.0544 | K22: 31.2869 | L22: =FALSE() -> FALSE | M22: very_high
A23: 37 | B23: 673384 | C23: 25992 | D23: 270934 | E23: 10569 | F23: 944318 | G23: 36561 | H23: Faisal | I23: Line2 | J23: 30.0169 | K23: 31.2072 | L23: =FALSE() -> FALSE | M23: very_high
A24: 79 | B24: 674294 | C24: 25915 | D24: 267958 | E24: 10432 | F24: 942252 | G24: 36347 | H24: Attaba | I24: Transfer_Line2/Line3 | J24: 30.0522 | K24: 31.2519 | L24: =TRUE() -> TRUE | M24: very_high
A25: 11 | B25: 668765 | C25: 25933 | D25: 273223 | E25: 10447 | F25: 941988 | G25: 36380 | H25: El Maadi | I25: Line1 | J25: 29.9611 | K25: 31.2567 | L25: =FALSE() -> FALSE | M25: very_high
A26: 21 | B26: 664234 | C26: 25829 | D26: 276322 | E26: 10732 | F26: 940556 | G26: 36561 | H26: El Demerdash | I26: Line1 | J26: 30.0772 | K26: 31.2778 | L26: =FALSE() -> FALSE | M26: very_high
A27: 17 | B27: 662802 | C27: 25675 | D27: 275264 | E27: 10430 | F27: 938066 | G27: 36105 | H27: Sayeda Zeinab | I27: Line1 | J27: 30.0292 | K27: 31.2431 | L27: =FALSE() -> FALSE | M27: very_high
A28: 20 | B28: 661959 | C28: 25734 | D28: 274416 | E28: 10617 | F28: 936375 | G28: 36351 | H28: Ghamra | I28: Line1 | J28: 30.0689 | K28: 31.2644 | L28: =FALSE() -> FALSE | M28: very_high
A29: 78 | B29: 663716 | C29: 25700 | D29: 268080 | E29: 10447 | F29: 931796 | G29: 36147 | H29: Al Shohadaa | I29: Transfer_Line1/Line2 | J29: 30.0617 | K29: 31.2461 | L29: =TRUE() -> TRUE | M29: extreme
A30: 55 | B30: 664464 | C30: 25964 | D30: 267224 | E30: 10517 | F30: 931688 | G30: 36481 | H30: El Nozha | I30: Line3 | J30: 30.1306 | K30: 31.3408 | L30: =FALSE() -> FALSE | M30: very_high
A31: 25 | B31: 55754 | C31: 2134 | D31: 292915 | E31: 11060 | F31: 348669 | G31: 13194 | H31: Saray El Qobba | I31: Line1 | J31: 30.1017 | K31: 31.3056 | L31: =FALSE() -> FALSE | M31: medium
A32: 52 | B32: 57665 | C32: 2197 | D32: 290197 | E32: 11158 | F32: 347862 | G32: 13355 | H32: Omar Ibn El Khattab | I32: Line3 | J32: 30.1406 | K32: 31.3892 | L32: =FALSE() -> FALSE | M32: high
A33: 73 | B33: 57843 | C33: 2154 | D33: 288108 | E33: 10841 | F33: 345951 | G33: 12995 | H33: El Bohy | I33: Line3 | J33: 30.0367 | K33: 31.2017 | L33: =FALSE() -> FALSE | M33: medium
A34: 8 | B34: 58305 | C34: 2184 | D34: 287444 | E34: 10890 | F34: 345749 | G34: 13074 | H34: Kozzika | I34: Line1 | J34: 29.9361 | K34: 31.2808 | L34: =FALSE() -> FALSE | M34: low
A35: 63 | B35: 54558 | C35: 2093 | D35: 290519 | E35: 10967 | F35: 345077 | G35: 13060 | H35: Fair Zone | I35: Line3 | J35: 30.0444 | K35: 31.2822 | L35: =FALSE() -> FALSE | M35: high
A36: 35 | B36: 56091 | C36: 2111 | D36: 287749 | E36: 11095 | F36: 343840 | G36: 13206 | H36: Omm El Masryeen | I36: Line2 | J36: 30.01 | K36: 31.2061 | L36: =FALSE() -> FALSE | M36: medium
A37: 39 | B37: 57905 | C37: 2198 | D37: 285437 | E37: 11043 | F37: 343342 | G37: 13241 | H37: El Bohoos | I37: Line2 | J37: 30.0333 | K37: 31.2094 | L37: =FALSE() -> FALSE | M37: high
A38: 19 | B38: 58539 | C38: 2232 | D38: 284711 | E38: 10907 | F38: 343250 | G38: 13139 | H38: Orabi | I38: Line1 | J38: 30.0567 | K38: 31.2422 | L38: =FALSE() -> FALSE | M38: high
A39: 75 | B39: 57772 | C39: 2149 | D39: 285170 | E39: 10914 | F39: 342942 | G39: 13063 | H39: Ring Road | I39: Line3 | J39: 30.0311 | K39: 31.1894 | L39: =FALSE() -> FALSE | M39: high
A40: 24 | B40: 57854 | C40: 2177 | D40: 285051 | E40: 10940 | F40: 342905 | G40: 13117 | H40: Hammamat El Qobba | I40: Line1 | J40: 30.095 | K40: 31.3 | L40: =FALSE() -> FALSE | M40: medium
...

Sheet Raw_DelaySummary
A1: station_id | B1: station_name | C1: line_id | D1: number_of_delays | E1: total_delay_duration_min | F1: avg_delay_duration_min | G1: most_common_reason | H1: most_common_event_type
A2: 18 | B2: Saad Zaghloul | C2: Line1 | D2: 32 | E2: 2442 | F2: 76.3125 | G2: mechanical_failure | H2: Overcrowding
A3: 38 | B3: Cairo University | C3: Line2 | D3: 27 | E3: 2372 | F3: 87.851852 | G3: signal_failure | H3: Maintenance
A4: 29 | B4: Ain Shams | C4: Line1 | D4: 26 | E4: 2239 | F4: 86.115385 | G4: power_issue | H4: Train Breakdown
A5: 68 | B5: Maspero | C5: Line3 | D5: 25 | E5: 1884 | F5: 75.36 | G5: weather_related | H5: Technical Failure
A6: 58 | B6: Heliopolis Square | C6: Line3 | D6: 27 | E6: 1878 | F6: 69.555556 | G6: weather_related | H6: Maintenance
A7: 17 | B7: Sayeda Zeinab | C7: Line1 | D7: 23 | E7: 1836 | F7: 79.826087 | G7: mechanical_failure | H7: Power Outage
A8: 40 | B8: Dokki | C8: Line2 | D8: 25 | E8: 1790 | F8: 71.6 | G8: weather_related | H8: Overcrowding
A9: 78 | B9: Al Shohadaa | C9: Transfer_Line1/Line2 | D9: 26 | E9: 1634 | F9: 62.846154 | G9: track_maintenance | H9: Technical Failure
A10: 64 | B10: Abbassia | C10: Line3 | D10: 26 | E10: 1596 | F10: 61.384615 | G10: mechanical_failure | H10: Track Issue
A11: 77 | B11: Sadat | C11: Transfer_Line1/Line2 | D11: 23 | E11: 1551 | F11: 67.434783 | G11: track_maintenance | H11: Technical Failure
A12: 80 | B12: Nasser | C12: Transfer_Line1/Line3 | D12: 17 | E12: 1495 | F12: 87.941176 | G12: power_issue | H12: Signal Problem
A13: 79 | B13: Attaba | C13: Transfer_Line2/Line3 | D13: 24 | E13: 1494 | F13: 62.25 | G13: overcrowding | H13: Signal Problem
... A80: 30 | B80: Ezbet El Nakhl | C80: Line1 | D80: 1 | E80: 12 | F80: 12 | G80: mechanical_failure | H80: Delay

Sheet Raw_ODPairsTop
A1: origin_station_id | B1: destination_station_id | C1: total_trips | D1: total_passengers | E1: total_revenue_egp | F1: origin_name | G1: origin_line | H1: destination_name | I1: destination_line
A2: 77 | B2: 2 | C2: 385 | D2: 9369 | E2: 125174 | F2: Sadat | G2: Transfer_Line1/Line2 | H2: Ain Helwan | I2: Line1
A3: 72 | B3: 47 | C3: 381 | D3: 10174 | E3: 132450 | F3: Imbaba | G3: Line3 | H3: Mezallat | I3: Line2
A4: 41 | B4: 62 | C4: 380 | D4: 10089 | E4: 132198 | F4: Opera | G4: Line2 | H4: Stadium | I4: Line3
A5: 70 | B5: 34 | C5: 379 | D5: 9967 | E5: 134248 | F5: Kit Kat | G5: Line3 | H5: Sakiat Mekky | I5: Line2
A6: 3 | B6: 36 | C6: 377 | D6: 9723 | E6: 125129 | F6: Helwan University | G6: Line1 | H6: Giza | I6: Line2
A7: 50 | B7: 48 | C7: 377 | D7: 9723 | E7: 126999 | F7: Adly Mansour | G7: Line3 | H7: Koliet El Zeraa | I7: Line2
A8: 77 | B8: 52 | C8: 377 | D8: 10435 | E8: 139332 | F8: Sadat | G8: Transfer_Line1/Line2 | H8: Omar Ibn El Khattab | I8: Line3
A9: 80 | B9: 13 | C9: 375 | D9: 10124 | E9: 133449 | F9: Nasser | G9: Transfer_Line1/Line3 | H9: Dar El Salam | I9: Line1
A10: 58 | B10: 21 | C10: 375 | D10: 8465 | E10: 110743 | F10: Heliopolis Square | G10: Line3 | H10: El Demerdash | I10: Line1
A11: 18 | B11: 35 | C11: 374 | D11: 9806 | E11: 128875 | F11: Saad Zaghloul | G11: Line1 | H11: Omm El Masryeen | I11: Line2
A12: 40 | B12: 1 | C12: 373 | D12: 9067 | E12: 118539 | F12: Dokki | G12: Line2 | H12: Helwan | I12: Line1
A13: 80 | B13: 21 | C13: 373 | D13: 10340 | E13: 137854 | F13: Nasser | G13: Transfer_Line1/Line3 | H13: El Demerdash | I13: Line1
... A51: 72 | B51: 67 | C51: 365 | D51: 9647 | E51: 77176 | F51: Imbaba | G51: Line3 | H51: Bab El Shaaria | I51: Line3

Sheet Raw_SegmentByDayType
A1: day_type | B1: n_days | C1: total_trips | D1: total_passengers | E1: total_revenue_egp | F1: avg_passengers_per_day | G1: avg_revenue_per_day | H1: avg_trips_per_day | I1: avg_ticket_price | J1: label
A2: holiday | B2: 18 | C2: 16917 | D2: 439779 | E2: 5440731 | F2: 24432.167 | G2: 302262.83 | H2: 939.83333 | I2: 12.371512 | J2: Public Holiday
A3: ramadan | B3: 30 | C3: 76894 | D3: 1997889 | E3: 24702195 | F3: 66596.3 | G3: 823406.5 | H3: 2563.1333 | I3: 12.364148 | J3: Ramadan
A4: regular | B4: 193 | C4: 496944 | D4: 12898024 | E4: 159567077 | F4: 66829.14 | G4: 826772.42 | H4: 2574.8394 | I4: 12.371436 | J4: Regular Day
A5: school_holiday | B5: 125 | C5: 271818 | D5: 7043160 | E5: 87183479 | F5: 56345.28 | G5: 697467.83 | H5: 2174.544 | I5: 12.378461 | J5: School Holiday

Sheet Raw_WeatherImpact
A1: weather_desc | B1: avg_temp_celsius | C1: total_trips | D1: total_passengers | E1: avg_daily_revenue | F1: avg_passenger_count
A2: Chilly | B2: 11.647648 | C2: 13433 | D2: 357909 | E2: 55631.838 | F2: 26.644011
A3: Clear | B3: 27.059336 | C3: 236941 | D3: 6130407 | E3: 210091.18 | F3: 25.873137
A4: Cold | B4: 11.971975 | C4: 20254 | D4: 518439 | E4: 72161.022 | F4: 25.59687
A5: Cool | B5: 12.247671 | C5: 34498 | D5: 914579 | E5: 124131.8 | F5: 26.511073
A6: Dusty | B6: 27.538047 | C6: 112160 | D6: 2868883 | E6: 103154.3 | F6: 25.578486
A7: Extremely Hot | B7: 39.410912 | C7: 40491 | D7: 1046005 | E7: 140864.8 | F7: 25.833025
A8: Heat Wave | B8: 39.541058 | C8: 26184 | D8: 668942 | E8: 91974.822 | F8: 25.547739
A9: Mild | B9: 22.72905 | C9: 28365 | D9: 796710 | E9: 114574.15 | F9: 28.087784
A10: Partly Cloudy | B10: 27.264694 | C10: 141433 | D10: 3599369 | E10: 124363.19 | F10: 25.449287
A11: Perfect | B11: 22.795249 | C11: 23289 | D11: 650823 | E11: 90301.236 | F11: 27.945511
A12: Pleasant | B12: 22.726921 | C12: 30617 | D12: 836105 | E12: 120059.6 | F12: 27.308521
A13: Sunny | B13: 26.976066 | C13: 87345 | D13: 2215459 | E13: 85459.698 | F13: 25.364463
A14: Very Hot | B14: 39.386422 | C14: 67563 | D14: 1775222 | E14: 239015.45 | F14: 26.275062
